Workbook
Name Category: OFFSET(Sheet3!$AF$3,1,0,COUNT(Sheet3!$AG$3:$AG$8))
Name Slicer_Month: #N/A
Name Slicer_Month1: #N/A
Name Slicer_PAYMENT_MODE: #N/A
Name Slicer_PAYMENT_MODE1: #N/A
Name Slicer_SALE_TYPE: #N/A
Name Slicer_SALE_TYPE1: #N/A
Name Slicer_Year: #N/A
Name Slicer_Year1: #N/A

Sheet Sheet3
M1: TRUE | N1: TRUE | O1: TRUE | V1: =VLOOKUP(1,U4:X91,2,0) -> Product41 | W1: =VLOOKUP(1,U4:X91,3,0) -> 18216 | X1: =VLOOKUP(1,U4:X91,4,0) -> 132
Z2: 1 | AA2: =COUNT(S4:S91)-9 -> 79 | AB2: =MIN(Z2:AA2) -> 1 | AI2: =VLOOKUP(1,$AH$4:$AJ$8,2,0) -> Category04 | AJ2: =VLOOKUP(1,$AH$4:$AJ$8,3,0) -> 95269.4
A3: Row Labels | B3: Sum of Total Selling | E3: Sum of Total Buying | F3: Sum of Total Selling | H3: Month | I3: Sum of Total Buying | J3: Sum of Total Selling | L3: Month | M3: Sales | N3: Profit | O3: Profit% | Q3: Product | R3: Sum of Total Buying | S3: Sum of QUANTITY | AF3: Category | AG3: Total | AM3: SALES TYPE | AN3: TOTAL | AP3: PAYMENT MODE | AQ3: Total
A4: 1 | B4: 13167.81 | D4: Total | E4: 332504 | F4: 401411.92 | H4: Jan | I4: 34290 | J4: 41346.96 | L4: Jan | M4: =IF($M$1=TRUE,VLOOKUP(L4,H3:J15,3,0),NA()) -> 41346.96 | N4: =IF($N$1=TRUE,VLOOKUP(L4,H2:J14,3,0)-VLOOKUP(L4,H2:J14,2,0),NA()) -> 7056.96 | O4: =IF($O$1=TRUE,N4/VLOOKUP(L4,H2:J14,2,0)," ") -> 0.20580227 | Q4: Product01 | R4: 9212 | S4: 94 | U4: {=RANK(_xlfn.ANCHORARRAY(W4),_xlfn.ANCHORARRAY(W4))} -> 29 | V4: {=OFFSET($Q$3,1,0,COUNT($R$3:$R$91))} -> Product01 | W4: {=OFFSET($Q$3,1,1,COUNT($R$3:$R$91))} -> 9212 | X4: {=OFFSET($Q$3,1,2,COUNT($R$3:$R$91))} -> 94 | Z4: {=OFFSET($Q$3,$Z$2,0,10)} -> Product01 | AA4: {=OFFSET($Q$3,1,$Z$2,10)} -> 9212 | AF4: Category01 | AG4: 68680.31 | AH4: {=RANK(_xlfn.ANCHORARRAY(AJ4),_xlfn.ANCHORARRAY(AJ4))} -> 4 | AI4: {=OFFSET($AF$3,1,0,COUNT($AG$3:$AG$8))} -> Category01 | AJ4: {=OFFSET(AG3:AG8,1,0,COUNT($AG$3:$AG$8))} -> 68680.31 | AM4: Direct Sales | AN4: 208140.15 | AP4: Cash | AQ4: 200583.94
A5: 2 | B5: 13210.22 | H5: Feb | I5: 25341 | J5: 30857.3 | L5: Feb | M5: =IF($M$1=TRUE,VLOOKUP(L5,H4:J16,3,0),NA()) -> 30857.3 | N5: =IF($N$1=TRUE,VLOOKUP(L5,H3:J15,3,0)-VLOOKUP(L5,H3:J15,2,0),NA()) -> 5516.3 | O5: =IF($O$1=TRUE,N5/VLOOKUP(L5,H3:J15,2,0)," ") -> 0.21768281 | Q5: Kg | R5: 9212 | S5: 94 | U5: 29 | V5: Kg | W5: 9212 | X5: 94 | Z5: Kg | AA5: 9212 | AF5: Category02 | AG5: 92963.87 | AH5: 2 | AI5: Category02 | AJ5: 92963.87 | AM5: Online | AN5: 133923.87 | AP5: Online | AQ5: 200827.98
A6: 3 | B6: 20202.1 | H6: Mar | I6: 23437 | J6: 28616.65 | L6: Mar | M6: =IF($M$1=TRUE,VLOOKUP(L6,H5:J17,3,0),NA()) -> 28616.65 | N6: =IF($N$1=TRUE,VLOOKUP(L6,H4:J16,3,0)-VLOOKUP(L6,H4:J16,2,0),NA()) -> 5179.65 | O6: =IF($O$1=TRUE,N6/VLOOKUP(L6,H4:J16,2,0)," ") -> 0.22100311 | Q6: Product02 | R6: 9870 | S6: 94 | U6: 21 | V6: Product02 | W6: 9870 | X6: 94 | Z6: Product02 | AA6: 9870 | AF6: Category03 | AG6: 52881.15 | AH6: 5 | AI6: Category03 | AJ6: 52881.15 | AM6: Wholesaler | AN6: 59347.9
A7: 4 | B7: 11312.2 | H7: Apr | I7: 21282 | J7: 26579.11 | L7: Apr | M7: =IF($M$1=TRUE,VLOOKUP(L7,H6:J18,3,0),NA()) -> 26579.11 | N7: =IF($N$1=TRUE,VLOOKUP(L7,H5:J17,3,0)-VLOOKUP(L7,H5:J17,2,0),NA()) -> 5297.11 | O7: =IF($O$1=TRUE,N7/VLOOKUP(L7,H5:J17,2,0)," ") -> 0.24890095 | Q7: Kg | R7: 9870 | S7: 94 | U7: 21 | V7: Kg | W7: 9870 | X7: 94 | Z7: Kg | AA7: 9870 | AF7: Category04 | AG7: 95269.4 | AH7: 1 | AI7: Category04 | AJ7: 95269.4
A8: 5 | B8: 11711.45 | H8: May | I8: 26526 | J8: 30910.45 | L8: May | M8: =IF($M$1=TRUE,VLOOKUP(L8,H7:J19,3,0),NA()) -> 30910.45 | N8: =IF($N$1=TRUE,VLOOKUP(L8,H6:J18,3,0)-VLOOKUP(L8,H6:J18,2,0),NA()) -> 4384.45 | O8: =IF($O$1=TRUE,N8/VLOOKUP(L8,H6:J18,2,0)," ") -> 0.16528877 | Q8: Product03 | R8: 5609 | S8: 79 | U8: 51 | V8: Product03 | W8: 5609 | X8: 79 | Z8: Product03 | AA8: 5609 | AF8: Category05 | AG8: 91617.19 | AH8: 3 | AI8: Category05 | AJ8: 91617.19
A9: 6 | B9: 14365.54 | H9: Jun | I9: 24879 | J9: 30533.71 | L9: Jun | M9: =IF($M$1=TRUE,VLOOKUP(L9,H8:J20,3,0),NA()) -> 30533.71 | N9: =IF($N$1=TRUE,VLOOKUP(L9,H7:J19,3,0)-VLOOKUP(L9,H7:J19,2,0),NA()) -> 5654.71 | O9: =IF($O$1=TRUE,N9/VLOOKUP(L9,H7:J19,2,0)," ") -> 0.22728848 | Q9: Kg | R9: 5609 | S9: 79 | U9: 51 | V9: Kg | W9: 5609 | X9: 79 | Z9: Kg | AA9: 5609
A10: 7 | B10: 7132.79 | H10: Jul | I10: 29878 | J10: 35251.79 | L10: Jul | M10: =IF($M$1=TRUE,VLOOKUP(L10,H9:J21,3,0),NA()) -> 35251.79 | N10: =IF($N$1=TRUE,VLOOKUP(L10,H8:J20,3,0)-VLOOKUP(L10,H8:J20,2,0),NA()) -> 5373.79 | O10: =IF($O$1=TRUE,N10/VLOOKUP(L10,H8:J20,2,0)," ") -> 0.17985775 | Q10: Product04 | R10: 5456 | S10: 124 | U10: 55 | V10: Product04 | W10: 5456 | X10: 124 | Z10: Product04 | AA10: 5456
A11: 8 | B11: 14262.46 | H11: Aug | I11: 29831 | J11: 35350.4 | L11: Aug | M11: =IF($M$1=TRUE,VLOOKUP(L11,H10:J22,3,0),NA()) -> 35350.4 | N11: =IF($N$1=TRUE,VLOOKUP(L11,H9:J21,3,0)-VLOOKUP(L11,H9:J21,2,0),NA()) -> 5519.4 | O11: =IF($O$1=TRUE,N11/VLOOKUP(L11,H9:J21,2,0)," ") -> 0.18502229 | Q11: Lt | R11: 5456 | S11: 124 | U11: 55 | V11: Lt | W11: 5456 | X11: 124 | Z11: Lt | AA11: 5456
A12: 9 | B12: 16824.67 | H12: Sep | I12: 28758 | J12: 35242.81 | L12: Sep | M12: =IF($M$1=TRUE,VLOOKUP(L12,H11:J23,3,0),NA()) -> 35242.81 | N12: =IF($N$1=TRUE,VLOOKUP(L12,H10:J22,3,0)-VLOOKUP(L12,H10:J22,2,0),NA()) -> 6484.81 | O12: =IF($O$1=TRUE,N12/VLOOKUP(L12,H10:J22,2,0)," ") -> 0.22549586 | Q12: Product05 | R12: 13433 | S12: 101 | U12: 13 | V12: Product05 | W12: 13433 | X12: 101 | Z12: Product05 | AA12: 13433
A13: 10 | B13: 15229.35 | H13: Oct | I13: 27842 | J13: 33500.69 | L13: Oct | M13: =IF($M$1=TRUE,VLOOKUP(L13,H12:J24,3,0),NA()) -> 33500.69 | N13: =IF($N$1=TRUE,VLOOKUP(L13,H11:J23,3,0)-VLOOKUP(L13,H11:J23,2,0),NA()) -> 5658.69 | O13: =IF($O$1=TRUE,N13/VLOOKUP(L13,H11:J23,2,0)," ") -> 0.20324294 | Q13: Ft | R13: 13433 | S13: 101 | U13: 13 | V13: Ft | W13: 13433 | X13: 101 | Z13: Ft | AA13: 13433
A14: 11 | B14: 11915.58 | H14: Nov | I14: 29306 | J14: 36124.07 | L14: Nov | M14: =IF($M$1=TRUE,VLOOKUP(L14,H13:J25,3,0),NA()) -> 36124.07 | N14: =IF($N$1=TRUE,VLOOKUP(L14,H12:J24,3,0)-VLOOKUP(L14,H12:J24,2,0),NA()) -> 6818.07 | O14: =IF($O$1=TRUE,N14/VLOOKUP(L14,H12:J24,2,0)," ") -> 0.23265099 | Q14: Product06 | R14: 3975 | S14: 53 | U14: 69 | V14: Product06 | W14: 3975 | X14: 53
A15: 12 | B15: 14837.36 | H15: Dec | I15: 31134 | J15: 37097.98 | L15: Dec | M15: =IF($M$1=TRUE,VLOOKUP(L15,H14:J26,3,0),NA()) -> 37097.98 | N15: =IF($N$1=TRUE,VLOOKUP(L15,H13:J25,3,0)-VLOOKUP(L15,H13:J25,2,0),NA()) -> 5963.98 | O15: =IF($O$1=TRUE,N15/VLOOKUP(L15,H13:J25,2,0)," ") -> 0.19155842 | Q15: Kg | R15: 3975 | S15: 53 | U15: 69 | V15: Kg | W15: 3975 | X15: 53
A16: 13 | B16: 8084.26 | Q16: Product07 | R16: 2064 | S16: 48 | U16: 75 | V16: Product07 | W16: 2064 | X16: 48
A17: 14 | B17: 9461.14 | Q17: Lt | R17: 2064 | S17: 48 | U17: 75 | V17: Lt | W17: 2064 | X17: 48
A18: 15 | B18: 12189.7 | Q18: Product08 | R18: 9213 | S18: 111 | U18: 27 | V18: Product08 | W18: 9213 | X18: 111
A19: 16 | B19: 12762.63 | Q19: Kg | R19: 9213 | S19: 111 | U19: 27 | V19: Kg | W19: 9213 | X19: 111
A20: 17 | B20: 3659.24 | Q20: Product09 | R20: 444 | S20: 74 | U20: 87 | V20: Product09 | W20: 444 | X20: 74
A21: 18 | B21: 18582.39 | Q21: No. | R21: 444 | S21: 74 | U21: 87 | V21: No. | W21: 444 | X21: 74
A22: 19 | B22: 10204.23 | Q22: Product10 | R22: 14800 | S22: 100 | U22: 9 | V22: Product10 | W22: 14800 | X22: 100
A23: 20 | B23: 20482.78 | Q23: Ft | R23: 14800 | S23: 100 | U23: 9 | V23: Ft | W23: 14800 | X23: 100
A24: 21 | B24: 10665.4 | D24: Total Sales | E24: =GETPIVOTDATA("Sum of Total Selling",$E$3) -> 401411.92 | Q24: Product11 | R24: 5324 | S24: 121 | U24: 57 | V24: Product11 | W24: 5324 | X24: 121
A25: 22 | B25: 11315.84 | D25: Total Profit | E25: =GETPIVOTDATA("Sum of Total Selling",$E$3)-GETPIVOTDATA("Sum of Total Buying ",$E$3) -> 68907.92 | Q25: Lt | R25: 5324 | S25: 121 | U25: 57 | V25: Lt | W25: 5324 | X25: 121
A26: 23 | B26: 18818.19 | D26: Profit% | E26: =E25/GETPIVOTDATA("Sum of Total Buying ",$E$3) -> 0.20723937 | Q26: Product12 | R26: 8979 | S26: 123 | U26: 31 | V26: Product12 | W26: 8979 | X26: 123
A27: 24 | B27: 11488.4 | Q27: Kg | R27: 8979 | S27: 123 | U27: 31 | V27: Kg | W27: 8979 | X27: 123
A28: 25 | B28: 18688.43 | Q28: Product13 | R28: 7728 | S28: 69 | U28: 43 | V28: Product13 | W28: 7728 | X28: 69
A29: 26 | B29: 13710.08 | Q29: Kg | R29: 7728 | S29: 69 | U29: 43 | V29: Kg | W29: 7728 | X29: 69
A30: 27 | B30: 11440.67 | Q30: Product14 | R30: 9744 | S30: 87 | U30: 23 | V30: Product14 | W30: 9744 | X30: 87
A31: 28 | B31: 13306.16 | Q31: Kg | R31: 9744 | S31: 87 | U31: 23 | V31: Kg | W31: 9744 | X31: 87
A32: 29 | B32: 8794.48 | Q32: Product15 | R32: 1404 | S32: 117 | U32: 81 | V32: Product15 | W32: 1404 | X32: 117
A33: 30 | B33: 16666.27 | Q33: No. | R33: 1404 | S33: 117 | U33: 81 | V33: No. | W33: 1404 | X33: 117
A34: 31 | B34: 6920.1 | Q34: Product16 | R34: 1560 | S34: 120 | U34: 79 | V34: Product16 | W34: 1560 | X34: 120
A35: Grand Total | B35: 401411.92 | Q35: No. | R35: 1560 | S35: 120 | U35: 79 | V35: No. | W35: 1560 | X35: 120
Q36: Product17 | R36: 8442 | S36: 63 | U36: 37 | V36: Product17 | W36: 8442 | X36: 63
Q37: Ft | R37: 8442 | S37: 63 | U37: 37 | V37: Ft | W37: 8442 | X37: 63
Q38: Product18 | R38: 3034 | S38: 82 | U38: 73 | V38: Product18 | W38: 3034 | X38: 82
Q39: No. | R39: 3034 | S39: 82 | U39: 73 | V39: No. | W39: 3034 | X39: 82
Q40: Product19 | R40: 14400 | S40: 96 | U40: 11 | V40: Product19 | W40: 14400 | X40: 96
...

Sheet Data 1
A1: Date | B1: PRODUCT ID | C1: QUANTITY | D1: SALE TYPE | E1: PAYMENT MODE | F1: DISCOUNT % | G1: PRODUCT | H1: CATEGORY | I1: UOM | J1: BUYING PRIZE | K1: SELLING PRICE | L1: Total Buying | M1: Total Selling | N1: Total Profit | O1: Day | P1: Month | Q1: Year
A2: 44197 | B2: P0024 | C2: 9 | D2: Wholesaler | E2: Online | F2: 0 | G2: =VLOOKUP('Data 1'!$B2,'Data 2'!$A$1:$F$46,MATCH('Data 1'!G$1,'Data 2'!$A$1:$F$1,0),0) -> Product24 | H2: =VLOOKUP('Data 1'!$B2,'Data 2'!$A$1:$F$46,MATCH('Data 1'!H$1,'Data 2'!$A$1:$F$1,0),0) -> Category03 | I2: =VLOOKUP('Data 1'!$B2,'Data 2'!$A$1:$F$46,MATCH('Data 1'!I$1,'Data 2'!$A$1:$F$1,0),0) -> Ft | J2: =VLOOKUP('Data 1'!$B2,'Data 2'!$A$1:$F$46,MATCH('Data 1'!J$1,'Data 2'!$A$1:$F$1,0),0) -> 144 | K2: =VLOOKUP('Data 1'!$B2,'Data 2'!$A$1:$F$46,MATCH('Data 1'!K$1,'Data 2'!$A$1:$F$1,0),0) -> 156.96 | L2: =SUM('Data 1'!$J2*'Data 1'!$C2) -> 1296 | M2: ='Data 1'!$C2*'Data 1'!$K2 -> 1412.64 | N2: ='Data 1'!$M2-'Data 1'!$L2 -> 116.64 | O2: =DAY('Data 1'!$A2) -> 1 | P2: =TEXT('Data 1'!$A2,"mmm") -> Jan | Q2: =YEAR('Data 1'!$A2) -> 2021
A3: 44198 | B3: P0038 | C3: 15 | D3: Online | E3: Cash | F3: 0 | G3: =VLOOKUP('Data 1'!$B3,'Data 2'!$A$1:$F$46,MATCH('Data 1'!G$1,'Data 2'!$A$1:$F$1,0),0) -> Product38 | H3: =VLOOKUP('Data 1'!$B3,'Data 2'!$A$1:$F$46,MATCH('Data 1'!H$1,'Data 2'!$A$1:$F$1,0),0) -> Category05 | I3: =VLOOKUP('Data 1'!$B3,'Data 2'!$A$1:$F$46,MATCH('Data 1'!I$1,'Data 2'!$A$1:$F$1,0),0) -> Kg | J3: =VLOOKUP('Data 1'!$B3,'Data 2'!$A$1:$F$46,MATCH('Data 1'!J$1,'Data 2'!$A$1:$F$1,0),0) -> 72 | K3: =VLOOKUP('Data 1'!$B3,'Data 2'!$A$1:$F$46,MATCH('Data 1'!K$1,'Data 2'!$A$1:$F$1,0),0) -> 79.92 | L3: =SUM('Data 1'!$J3*'Data 1'!$C3) -> 1080 | M3: ='Data 1'!$C3*'Data 1'!$K3 -> 1198.8 | N3: ='Data 1'!$M3-'Data 1'!$L3 -> 118.8 | O3: =DAY('Data 1'!$A3) -> 2 | P3: =TEXT('Data 1'!$A3,"mmm") -> Jan | Q3: =YEAR('Data 1'!$A3) -> 2021
A4: 44198 | B4: P0013 | C4: 6 | D4: Direct Sales | E4: Cash | F4: 0 | G4: =VLOOKUP('Data 1'!$B4,'Data 2'!$A$1:$F$46,MATCH('Data 1'!G$1,'Data 2'!$A$1:$F$1,0),0) -> Product13 | H4: =VLOOKUP('Data 1'!$B4,'Data 2'!$A$1:$F$46,MATCH('Data 1'!H$1,'Data 2'!$A$1:$F$1,0),0) -> Category02 | I4: =VLOOKUP('Data 1'!$B4,'Data 2'!$A$1:$F$46,MATCH('Data 1'!I$1,'Data 2'!$A$1:$F$1,0),0) -> Kg | J4: =VLOOKUP('Data 1'!$B4,'Data 2'!$A$1:$F$46,MATCH('Data 1'!J$1,'Data 2'!$A$1:$F$1,0),0) -> 112 | K4: =VLOOKUP('Data 1'!$B4,'Data 2'!$A$1:$F$46,MATCH('Data 1'!K$1,'Data 2'!$A$1:$F$1,0),0) -> 122.08 | L4: =SUM('Data 1'!$J4*'Data 1'!$C4) -> 672 | M4: ='Data 1'!$C4*'Data 1'!$K4 -> 732.48 | N4: ='Data 1'!$M4-'Data 1'!$L4 -> 60.48 | O4: =DAY('Data 1'!$A4) -> 2 | P4: =TEXT('Data 1'!$A4,"mmm") -> Jan | Q4: =YEAR('Data 1'!$A4) -> 2021
A5: 44199 | B5: P0004 | C5: 5 | D5: Direct Sales | E5: Online | F5: 0 | G5: =VLOOKUP('Data 1'!$B5,'Data 2'!$A$1:$F$46,MATCH('Data 1'!G$1,'Data 2'!$A$1:$F$1,0),0) -> Product04 | H5: =VLOOKUP('Data 1'!$B5,'Data 2'!$A$1:$F$46,MATCH('Data 1'!H$1,'Data 2'!$A$1:$F$1,0),0) -> Category01 | I5: =VLOOKUP('Data 1'!$B5,'Data 2'!$A$1:$F$46,MATCH('Data 1'!I$1,'Data 2'!$A$1:$F$1,0),0) -> Lt | J5: =VLOOKUP('Data 1'!$B5,'Data 2'!$A$1:$F$46,MATCH('Data 1'!J$1,'Data 2'!$A$1:$F$1,0),0) -> 44 | K5: =VLOOKUP('Data 1'!$B5,'Data 2'!$A$1:$F$46,MATCH('Data 1'!K$1,'Data 2'!$A$1:$F$1,0),0) -> 48.84 | L5: =SUM('Data 1'!$J5*'Data 1'!$C5) -> 220 | M5: ='Data 1'!$C5*'Data 1'!$K5 -> 244.2 | N5: ='Data 1'!$M5-'Data 1'!$L5 -> 24.2 | O5: =DAY('Data 1'!$A5) -> 3 | P5: =TEXT('Data 1'!$A5,"mmm") -> Jan | Q5: =YEAR('Data 1'!$A5) -> 2021
A6: 44200 | B6: P0035 | C6: 12 | D6: Online | E6: Online | F6: 0 | G6: =VLOOKUP('Data 1'!$B6,'Data 2'!$A$1:$F$46,MATCH('Data 1'!G$1,'Data 2'!$A$1:$F$1,0),0) -> Product35 | H6: =VLOOKUP('Data 1'!$B6,'Data 2'!$A$1:$F$46,MATCH('Data 1'!H$1,'Data 2'!$A$1:$F$1,0),0) -> Category04 | I6: =VLOOKUP('Data 1'!$B6,'Data 2'!$A$1:$F$46,MATCH('Data 1'!I$1,'Data 2'!$A$1:$F$1,0),0) -> No. | J6: =VLOOKUP('Data 1'!$B6,'Data 2'!$A$1:$F$46,MATCH('Data 1'!J$1,'Data 2'!$A$1:$F$1,0),0) -> 5 | K6: =VLOOKUP('Data 1'!$B6,'Data 2'!$A$1:$F$46,MATCH('Data 1'!K$1,'Data 2'!$A$1:$F$1,0),0) -> 6.7 | L6: =SUM('Data 1'!$J6*'Data 1'!$C6) -> 60 | M6: ='Data 1'!$C6*'Data 1'!$K6 -> 80.4 | N6: ='Data 1'!$M6-'Data 1'!$L6 -> 20.4 | O6: =DAY('Data 1'!$A6) -> 4 | P6: =TEXT('Data 1'!$A6,"mmm") -> Jan | Q6: =YEAR('Data 1'!$A6) -> 2021
A7: 44205 | B7: P0031 | C7: 1 | D7: Direct Sales | E7: Cash | F7: 0 | G7: =VLOOKUP('Data 1'!$B7,'Data 2'!$A$1:$F$46,MATCH('Data 1'!G$1,'Data 2'!$A$1:$F$1,0),0) -> Product31 | H7: =VLOOKUP('Data 1'!$B7,'Data 2'!$A$1:$F$46,MATCH('Data 1'!H$1,'Data 2'!$A$1:$F$1,0),0) -> Category04 | I7: =VLOOKUP('Data 1'!$B7,'Data 2'!$A$1:$F$46,MATCH('Data 1'!I$1,'Data 2'!$A$1:$F$1,0),0) -> Kg | J7: =VLOOKUP('Data 1'!$B7,'Data 2'!$A$1:$F$46,MATCH('Data 1'!J$1,'Data 2'!$A$1:$F$1,0),0) -> 93 | K7: =VLOOKUP('Data 1'!$B7,'Data 2'!$A$1:$F$46,MATCH('Data 1'!K$1,'Data 2'!$A$1:$F$1,0),0) -> 104.16 | L7: =SUM('Data 1'!$J7*'Data 1'!$C7) -> 93 | M7: ='Data 1'!$C7*'Data 1'!$K7 -> 104.16 | N7: ='Data 1'!$M7-'Data 1'!$L7 -> 11.16 | O7: =DAY('Data 1'!$A7) -> 9 | P7: =TEXT('Data 1'!$A7,"mmm") -> Jan | Q7: =YEAR('Data 1'!$A7) -> 2021
A8: 44205 | B8: P0003 | C8: 8 | D8: Direct Sales | E8: Cash | F8: 0 | G8: =VLOOKUP('Data 1'!$B8,'Data 2'!$A$1:$F$46,MATCH('Data 1'!G$1,'Data 2'!$A$1:$F$1,0),0) -> Product03 | H8: =VLOOKUP('Data 1'!$B8,'Data 2'!$A$1:$F$46,MATCH('Data 1'!H$1,'Data 2'!$A$1:$F$1,0),0) -> Category01 | I8: =VLOOKUP('Data 1'!$B8,'Data 2'!$A$1:$F$46,MATCH('Data 1'!I$1,'Data 2'!$A$1:$F$1,0),0) -> Kg | J8: =VLOOKUP('Data 1'!$B8,'Data 2'!$A$1:$F$46,MATCH('Data 1'!J$1,'Data 2'!$A$1:$F$1,0),0) -> 71 | K8: =VLOOKUP('Data 1'!$B8,'Data 2'!$A$1:$F$46,MATCH('Data 1'!K$1,'Data 2'!$A$1:$F$1,0),0) -> 80.94 | L8: =SUM('Data 1'!$J8*'Data 1'!$C8) -> 568 | M8: ='Data 1'!$C8*'Data 1'!$K8 -> 647.52 | N8: ='Data 1'!$M8-'Data 1'!$L8 -> 79.52 | O8: =DAY('Data 1'!$A8) -> 9 | P8: =TEXT('Data 1'!$A8,"mmm") -> Jan | Q8: =YEAR('Data 1'!$A8) -> 2021
A9: 44205 | B9: P0025 | C9: 4 | D9: Direct Sales | E9: Online | F9: 0 | G9: =VLOOKUP('Data 1'!$B9,'Data 2'!$A$1:$F$46,MATCH('Data 1'!G$1,'Data 2'!$A$1:$F$1,0),0) -> Product25 | H9: =VLOOKUP('Data 1'!$B9,'Data 2'!$A$1:$F$46,MATCH('Data 1'!H$1,'Data 2'!$A$1:$F$1,0),0) -> Category03 | I9: =VLOOKUP('Data 1'!$B9,'Data 2'!$A$1:$F$46,MATCH('Data 1'!I$1,'Data 2'!$A$1:$F$1,0),0) -> No. | J9: =VLOOKUP('Data 1'!$B9,'Data 2'!$A$1:$F$46,MATCH('Data 1'!J$1,'Data 2'!$A$1:$F$1,0),0) -> 7 | K9: =VLOOKUP('Data 1'!$B9,'Data 2'!$A$1:$F$46,MATCH('Data 1'!K$1,'Data 2'!$A$1:$F$1,0),0) -> 8.33 | L9: =SUM('Data 1'!$J9*'Data 1'!$C9) -> 28 | M9: ='Data 1'!$C9*'Data 1'!$K9 -> 33.32 | N9: ='Data 1'!$M9-'Data 1'!$L9 -> 5.32 | O9: =DAY('Data 1'!$A9) -> 9 | P9: =TEXT('Data 1'!$A9,"mmm") -> Jan | Q9: =YEAR('Data 1'!$A9) -> 2021
A10: 44207 | B10: P0037 | C10: 3 | D10: Direct Sales | E10: Cash | F10: 0 | G10: =VLOOKUP('Data 1'!$B10,'Data 2'!$A$1:$F$46,MATCH('Data 1'!G$1,'Data 2'!$A$1:$F$1,0),0) -> Product37 | H10: =VLOOKUP('Data 1'!$B10,'Data 2'!$A$1:$F$46,MATCH('Data 1'!H$1,'Data 2'!$A$1:$F$1,0),0) -> Category05 | I10: =VLOOKUP('Data 1'!$B10,'Data 2'!$A$1:$F$46,MATCH('Data 1'!I$1,'Data 2'!$A$1:$F$1,0),0) -> Kg | J10: =VLOOKUP('Data 1'!$B10,'Data 2'!$A$1:$F$46,MATCH('Data 1'!J$1,'Data 2'!$A$1:$F$1,0),0) -> 67 | K10: =VLOOKUP('Data 1'!$B10,'Data 2'!$A$1:$F$46,MATCH('Data 1'!K$1,'Data 2'!$A$1:$F$1,0),0) -> 85.76 | L10: =SUM('Data 1'!$J10*'Data 1'!$C10) -> 201 | M10: ='Data 1'!$C10*'Data 1'!$K10 -> 257.28 | N10: ='Data 1'!$M10-'Data 1'!$L10 -> 56.28 | O10: =DAY('Data 1'!$A10) -> 11 | P10: =TEXT('Data 1'!$A10,"mmm") -> Jan | Q10: =YEAR('Data 1'!$A10) -> 2021
A11: 44207 | B11: P0014 | C11: 4 | D11: Wholesaler | E11: Online | F11: 0 | G11: =VLOOKUP('Data 1'!$B11,'Data 2'!$A$1:$F$46,MATCH('Data 1'!G$1,'Data 2'!$A$1:$F$1,0),0) -> Product14 | H11: =VLOOKUP('Data 1'!$B11,'Data 2'!$A$1:$F$46,MATCH('Data 1'!H$1,'Data 2'!$A$1:$F$1,0),0) -> Category02 | I11: =VLOOKUP('Data 1'!$B11,'Data 2'!$A$1:$F$46,MATCH('Data 1'!I$1,'Data 2'!$A$1:$F$1,0),0) -> Kg | J11: =VLOOKUP('Data 1'!$B11,'Data 2'!$A$1:$F$46,MATCH('Data 1'!J$1,'Data 2'!$A$1:$F$1,0),0) -> 112 | K11: =VLOOKUP('Data 1'!$B11,'Data 2'!$A$1:$F$46,MATCH('Data 1'!K$1,'Data 2'!$A$1:$F$1,0),0) -> 146.72 | L11: =SUM('Data 1'!$J11*'Data 1'!$C11) -> 448 | M11: ='Data 1'!$C11*'Data 1'!$K11 -> 586.88 | N11: ='Data 1'!$M11-'Data 1'!$L11 -> 138.88 | O11: =DAY('Data 1'!$A11) -> 11 | P11: =TEXT('Data 1'!$A11,"mmm") -> Jan | Q11: =YEAR('Data 1'!$A11) -> 2021
A12: 44207 | B12: P0042 | C12: 4 | D12: Direct Sales | E12: Online | F12: 0 | G12: =VLOOKUP('Data 1'!$B12,'Data 2'!$A$1:$F$46,MATCH('Data 1'!G$1,'Data 2'!$A$1:$F$1,0),0) -> Product42 | H12: =VLOOKUP('Data 1'!$B12,'Data 2'!$A$1:$F$46,MATCH('Data 1'!H$1,'Data 2'!$A$1:$F$1,0),0) -> Category05 | I12: =VLOOKUP('Data 1'!$B12,'Data 2'!$A$1:$F$46,MATCH('Data 1'!I$1,'Data 2'!$A$1:$F$1,0),0) -> Ft | J12: =VLOOKUP('Data 1'!$B12,'Data 2'!$A$1:$F$46,MATCH('Data 1'!J$1,'Data 2'!$A$1:$F$1,0),0) -> 120 | K12: =VLOOKUP('Data 1'!$B12,'Data 2'!$A$1:$F$46,MATCH('Data 1'!K$1,'Data 2'!$A$1:$F$1,0),0) -> 162 | L12: =SUM('Data 1'!$J12*'Data 1'!$C12) -> 480 | M12: ='Data 1'!$C12*'Data 1'!$K12 -> 648 | N12: ='Data 1'!$M12-'Data 1'!$L12 -> 168 | O12: =DAY('Data 1'!$A12) -> 11 | P12: =TEXT('Data 1'!$A12,"mmm") -> Jan | Q12: =YEAR('Data 1'!$A12) -> 2021
A13: 44208 | B13: P0042 | C13: 10 | D13: Online | E13: Cash | F13: 0 | G13: =VLOOKUP('Data 1'!$B13,'Data 2'!$A$1:$F$46,MATCH('Data 1'!G$1,'Data 2'!$A$1:$F$1,0),0) -> Product42 | H13: =VLOOKUP('Data 1'!$B13,'Data 2'!$A$1:$F$46,MATCH('Data 1'!H$1,'Data 2'!$A$1:$F$1,0),0) -> Category05 | I13: =VLOOKUP('Data 1'!$B13,'Data 2'!$A$1:$F$46,MATCH('Data 1'!I$1,'Data 2'!$A$1:$F$1,0),0) -> Ft | J13: =VLOOKUP('Data 1'!$B13,'Data 2'!$A$1:$F$46,MATCH('Data 1'!J$1,'Data 2'!$A$1:$F$1,0),0) -> 120 | K13: =VLOOKUP('Data 1'!$B13,'Data 2'!$A$1:$F$46,MATCH('Data 1'!K$1,'Data 2'!$A$1:$F$1,0),0) -> 162 | L13: =SUM('Data 1'!$J13*'Data 1'!$C13) -> 1200 | M13: ='Data 1'!$C13*'Data 1'!$K13 -> 1620 | N13: ='Data 1'!$M13-'Data 1'!$L13 -> 420 | O13: =DAY('Data 1'!$A13) -> 12 | P13: =TEXT('Data 1'!$A13,"mmm") -> Jan | Q13: =YEAR('Data 1'!$A13) -> 2021
... A528: 44926 | B528: P0011 | C528: 3 | D528: Wholesaler | E528: Cash | F528: 0 | G528: =VLOOKUP('Data 1'!$B528,'Data 2'!$A$1:$F$46,MATCH('Data 1'!G$1,'Data 2'!$A$1:$F$1,0),0) -> Product11 | H528: =VLOOKUP('Data 1'!$B528,'Data 2'!$A$1:$F$46,MATCH('Data 1'!H$1,'Data 2'!$A$1:$F$1,0),0) -> Category02 | I528: =VLOOKUP('Data 1'!$B528,'Data 2'!$A$1:$F$46,MATCH('Data 1'!I$1,'Data 2'!$A$1:$F$1,0),0) -> Lt | J528: =VLOOKUP('Data 1'!$B528,'Data 2'!$A$1:$F$46,MATCH('Data 1'!J$1,'Data 2'!$A$1:$F$1,0),0) -> 44 | K528: =VLOOKUP('Data 1'!$B528,'Data 2'!$A$1:$F$46,MATCH('Data 1'!K$1,'Data 2'!$A$1:$F$1,0),0) -> 48.4 | L528: =SUM('Data 1'!$J528*'Data 1'!$C528) -> 132 | M528: ='Data 1'!$C528*'Data 1'!$K528 -> 145.2 | N528: ='Data 1'!$M528-'Data 1'!$L528 -> 13.2 | O528: =DAY('Data 1'!$A528) -> 31 | P528: =TEXT('Data 1'!$A528,"mmm") -> Dec | Q528: =YEAR('Data 1'!$A528) -> 2022
N529: =SUM(N2:N528) -> 68907.92

Sheet Prcatice_ans
L2: Sale Type | M2: Sum of Total Selling | P2: Category | Q2: Sum of Total Selling | S2: {=P3:Q3} -> Category04 | T2: 95269.4 | X2: Month | Y2: Sum of Total Buying | Z2: Sum of Total Profit | AA2: Sum of Total Selling | AC2: {=X2:AA14} -> Month | AD2: Sum of Total Buying | AE2: Sum of Total Profit | AF2: Sum of Total Selling | AG2: Profit %
A3: Sum of Total Buying | B3: Sum of Total Selling | C3: Sum of Total Profit | D3: Profit | F3: Year | G3: Sum of Total Selling | H3: Sum of Total Buying | L3: Direct Sales | M3: 208140.15 | P3: Category04 | Q3: 95269.4 | X3: Jan | Y3: 34290 | Z3: 7056.96 | AA3: 41346.96 | AC3: Jan | AD3: 34290 | AE3: 7056.96 | AF3: 41346.96 | AG3: =AE3/AD3 -> 0.20580227
A4: 332504 | B4: 401411.92 | C4: 68907.92 | D4: =GETPIVOTDATA("Sum of Total Profit",$A$3)/GETPIVOTDATA("Sum of Total Buying ",$A$3) -> 0.20723937 | F4: 2021 | G4: 187284.32 | H4: 156969 | L4: Online | M4: 133923.87 | P4: Category02 | Q4: 92963.87 | T4: =GETPIVOTDATA("Total Selling",$P$2,"CATEGORY","Category04") -> 95269.4 | X4: Feb | Y4: 25341 | Z4: 5516.3 | AA4: 30857.3 | AC4: Feb | AD4: 25341 | AE4: 5516.3 | AF4: 30857.3 | AG4: =AE4/AD4 -> 0.21768281
A5: =GETPIVOTDATA("Sum of Total Buying ",$A$3) -> 332504 | B5: =GETPIVOTDATA("Sum of Total Selling",$A$3) -> 401411.92 | C5: =GETPIVOTDATA("Sum of Total Profit",$A$3) -> 68907.92 | F5: 2022 | G5: 214127.6 | H5: 175535 | L5: Wholesaler | M5: 59347.9 | P5: Category05 | Q5: 91617.19 | X5: Mar | Y5: 23437 | Z5: 5179.65 | AA5: 28616.65 | AC5: Mar | AD5: 23437 | AE5: 5179.65 | AF5: 28616.65 | AG5: =AE5/AD5 -> 0.22100311
P6: Category01 | Q6: 68680.31 | X6: Apr | Y6: 21282 | Z6: 5297.11 | AA6: 26579.11 | AC6: Apr | AD6: 21282 | AE6: 5297.11 | AF6: 26579.11 | AG6: =AE6/AD6 -> 0.24890095
P7: Category03 | Q7: 52881.15 | X7: May | Y7: 26526 | Z7: 4384.45 | AA7: 30910.45 | AC7: May | AD7: 26526 | AE7: 4384.45 | AF7: 30910.45 | AG7: =AE7/AD7 -> 0.16528877
F8: Day | G8: Sum of Total Selling | I8: Category | J8: Sum of Total Selling | L8: Payment Mode | M8: Sum of Total Selling | T8: Rank | U8: Product | V8: Total selling | X8: Jun | Y8: 24879 | Z8: 5654.71 | AA8: 30533.71 | AC8: Jun | AD8: 24879 | AE8: 5654.71 | AF8: 30533.71 | AG8: =AE8/AD8 -> 0.22728848
F9: 1 | G9: 13167.81 | I9: Category01 | J9: 68680.31 | L9: Product01 | M9: 9764.72 | P9: =RANK(R9,$R$9:$R$52,0) -> 19 | Q9: {=OFFSET(L8,1,0,COUNTA(L9:L52),2)} -> Product01 | R9: 9764.72 | T9: 1 | U9: {=VLOOKUP(T9,$P$9:$R$52,{2,3},0)} -> Product41 | V9: 22952.16 | X9: Jul | Y9: 29878 | Z9: 5373.79 | AA9: 35251.79 | AC9: Jul | AD9: 29878 | AE9: 5373.79 | AF9: 35251.79 | AG9: =AE9/AD9 -> 0.17985775
F10: 2 | G10: 13210.22 | I10: Category02 | J10: 92963.87 | L10: Product02 | M10: 13423.2 | P10: =RANK(R10,$R$9:$R$52,0) -> 10 | Q10: Product02 | R10: 13423.2 | T10: 2 | U10: {=VLOOKUP(T10,$P$9:$R$52,{2,3},0)} -> Product30 | V10: 22945.92 | X10: Aug | Y10: 29831 | Z10: 5519.4 | AA10: 35350.4 | AC10: Aug | AD10: 29831 | AE10: 5519.4 | AF10: 35350.4 | AG10: =AE10/AD10 -> 0.18502229
F11: 3 | G11: 20202.1 | I11: Category03 | J11: 52881.15 | L11: Product03 | M11: 6394.26 | P11: =RANK(R11,$R$9:$R$52,0) -> 26 | Q11: Product03 | R11: 6394.26 | T11: 3 | U11: {=VLOOKUP(T11,$P$9:$R$52,{2,3},0)} -> Product42 | V11: 20574 | X11: Sep | Y11: 28758 | Z11: 6484.81 | AA11: 35242.81 | AC11: Sep | AD11: 28758 | AE11: 6484.81 | AF11: 35242.81 | AG11: =AE11/AD11 -> 0.22549586
F12: 4 | G12: 11312.2 | I12: Category04 | J12: 95269.4 | L12: Product04 | M12: 6056.16 | P12: =RANK(R12,$R$9:$R$52,0) -> 30 | Q12: Product04 | R12: 6056.16 | T12: 4 | U12: {=VLOOKUP(T12,$P$9:$R$52,{2,3},0)} -> Product19 | V12: 20160 | X12: Oct | Y12: 27842 | Z12: 5658.69 | AA12: 33500.69 | AC12: Oct | AD12: 27842 | AE12: 5658.69 | AF12: 33500.69 | AG12: =AE12/AD12 -> 0.20324294
F13: 5 | G13: 11711.45 | I13: Category05 | J13: 91617.19 | L13: Product05 | M13: 15716.61 | P13: =RANK(R13,$R$9:$R$52,0) -> 8 | Q13: Product05 | R13: 15716.61 | T13: 5 | U13: {=VLOOKUP(T13,$P$9:$R$52,{2,3},0)} -> Product10 | V13: 16428 | X13: Nov | Y13: 29306 | Z13: 6818.07 | AA13: 36124.07 | AC13: Nov | AD13: 29306 | AE13: 6818.07 | AF13: 36124.07 | AG13: =AE13/AD13 -> 0.23265099
F14: 6 | G14: 14365.54 | L14: Product06 | M14: 4531.5 | P14: =RANK(R14,$R$9:$R$52,0) -> 35 | Q14: Product06 | R14: 4531.5 | X14: Dec | Y14: 31134 | Z14: 5963.98 | AA14: 37097.98 | AC14: Dec | AD14: 31134 | AE14: 5963.98 | AF14: 37097.98 | AG14: =AE14/AD14 -> 0.19155842
F15: 7 | G15: 7132.79 | L15: Product07 | M15: 2291.04 | P15: =RANK(R15,$R$9:$R$52,0) -> 39 | Q15: Product07 | R15: 2291.04 | T15: Top Product
F16: 8 | G16: 14262.46 | I16: {=I8:J13} -> Category | J16: Sum of Total Selling | L16: Product08 | M16: 10502.82 | P16: =RANK(R16,$R$9:$R$52,0) -> 15 | Q16: Product08 | R16: 10502.82 | T16: {=T9:V9} -> 1 | U16: Product41 | V16: 22952.16
A17: Total Buying | F17: 9 | G17: 16824.67 | I17: Category01 | J17: 68680.31 | L17: Product09 | M17: 581.64 | P17: =RANK(R17,$R$9:$R$52,0) -> 44 | Q17: Product09 | R17: 581.64
A18: Total Sales | F18: 10 | G18: 15229.35 | I18: Category02 | J18: 92963.87 | L18: Product10 | M18: 16428 | P18: =RANK(R18,$R$9:$R$52,0) -> 5 | Q18: Product10 | R18: 16428
A19: Total Profit | F19: 11 | G19: 11915.58 | I19: Category03 | J19: 52881.15 | L19: Product11 | M19: 5856.4 | P19: =RANK(R19,$R$9:$R$52,0) -> 31 | Q19: Product11 | R19: 5856.4
A20: Profit% | F20: 12 | G20: 14837.36 | I20: Category04 | J20: 95269.4 | L20: Product12 | M20: 11582.91 | P20: =RANK(R20,$R$9:$R$52,0) -> 13 | Q20: Product12 | R20: 11582.91
F21: 13 | G21: 8084.26 | I21: Category05 | J21: 91617.19 | L21: Product13 | M21: 8423.52 | P21: =RANK(R21,$R$9:$R$52,0) -> 22 | Q21: Product13 | R21: 8423.52
A22: Year Wise sales,profit,Buying prize | F22: 14 | G22: 9461.14 | L22: Product14 | M22: 12764.64 | P22: =RANK(R22,$R$9:$R$52,0) -> 12 | Q22: Product14 | R22: 12764.64
A23: Day wise Sales | F23: 15 | G23: 12189.7 | L23: Product15 | M23: 1839.24 | P23: =RANK(R23,$R$9:$R$52,0) -> 41 | Q23: Product15 | R23: 1839.24
A24: Category wise sales | F24: 16 | G24: 12762.63 | L24: Product16 | M24: 1996.8 | P24: =RANK(R24,$R$9:$R$52,0) -> 40 | Q24: Product16 | R24: 1996.8
A25: Sale type wise sales | F25: 17 | G25: 3659.24 | L25: Product17 | M25: 9877.14 | P25: =RANK(R25,$R$9:$R$52,0) -> 18 | Q25: Product17 | R25: 9877.14
A26: Payment mode wise sales | F26: 18 | G26: 18582.39 | L26: Product18 | M26: 4035.22 | P26: =RANK(R26,$R$9:$R$52,0) -> 36 | Q26: Product18 | R26: 4035.22
F27: 19 | G27: 10204.23 | L27: Product19 | M27: 20160 | P27: =RANK(R27,$R$9:$R$52,0) -> 4 | Q27: Product19 | R27: 20160
A28: Top Product name and sales | F28: 20 | G28: 20482.78 | L28: Product20 | M28: 8006.25 | P28: =RANK(R28,$R$9:$R$52,0) -> 23 | Q28: Product20 | R28: 8006.25
A29: Top category name and sales | F29: 21 | G29: 10665.4 | L29: Product21 | M29: 10727.64 | P29: =RANK(R29,$R$9:$R$52,0) -> 14 | Q29: Product21 | R29: 10727.64
A30: Month wise Profit % and sales in combo chart | F30: 22 | G30: 11315.84 | L30: Product22 | M30: 9909.9 | P30: =RANK(R30,$R$9:$R$52,0) -> 17 | Q30: Product22 | R30: 9909.9
F31: 23 | G31: 18818.19 | L31: Product23 | M31: 12853.56 | P31: =RANK(R31,$R$9:$R$52,0) -> 11 | Q31: Product23 | R31: 12853.56
F32: 24 | G32: 11488.4 | L32: Product24 | M32: 10202.4 | P32: =RANK(R32,$R$9:$R$52,0) -> 16 | Q32: Product24 | R32: 10202.4
F33: 25 | G33: 18688.43 | L33: Product25 | M33: 599.76 | P33: =RANK(R33,$R$9:$R$52,0) -> 43 | Q33: Product25 | R33: 599.76
F34: 26 | G34: 13710.08 | L34: Product26 | M34: 2761.92 | P34: =RANK(R34,$R$9:$R$52,0) -> 38 | Q34: Product26 | R34: 2761.92
F35: 27 | G35: 11440.67 | L35: Product27 | M35: 6226.08 | P35: =RANK(R35,$R$9:$R$52,0) -> 28 | Q35: Product27 | R35: 6226.08
F36: 28 | G36: 13306.16 | L36: Product28 | M36: 4682.72 | P36: =RANK(R36,$R$9:$R$52,0) -> 34 | Q36: Product28 | R36: 4682.72
F37: 29 | G37: 8794.48 | L37: Product29 | M37: 5523.44 | P37: =RANK(R37,$R$9:$R$52,0) -> 32 | Q37: Product29 | R37: 5523.44
F38: 30 | G38: 16666.27 | L38: Product30 | M38: 22945.92 | P38: =RANK(R38,$R$9:$R$52,0) -> 2 | Q38: Product30 | R38: 22945.92
F39: 31 | G39: 6920.1 | L39: Product31 | M39: 6249.6 | P39: =RANK(R39,$R$9:$R$52,0) -> 27 | Q39: Product31 | R39: 6249.6
L40: Product32 | M40: 16329.72 | P40: =RANK(R40,$R$9:$R$52,0) -> 7 | Q40: Product32 | R40: 16329.72
L41: Product33 | M41: 13645.8 | P41: =RANK(R41,$R$9:$R$52,0) -> 9 | Q41: Product33 | R41: 13645.8
...

Sheet Practice
A1: Date | B1: PRODUCT ID | C1: QUANTITY | D1: SALE TYPE | E1: PAYMENT MODE | F1: DISCOUNT % | G1: PRODUCT | H1: CATEGORY | I1: UOM | J1: BUYING PRIZE | K1: SELLING PRICE | L1: Total Buying | M1: Total Selling | N1: Total Profit | O1: Day | P1: Month | Q1: Year
A2: 44197 | B2: P0024 | C2: 9 | D2: Wholesaler | E2: Online | F2: 0 | G2: =VLOOKUP('Data 1'!$B2,'Data 2'!$A$1:$F$46,MATCH('Data 1'!G$1,'Data 2'!$A$1:$F$1,0),0) -> Product24 | H2: =VLOOKUP('Data 1'!$B2,'Data 2'!$A$1:$F$46,MATCH('Data 1'!H$1,'Data 2'!$A$1:$F$1,0),0) -> Category03 | I2: =VLOOKUP('Data 1'!$B2,'Data 2'!$A$1:$F$46,MATCH('Data 1'!I$1,'Data 2'!$A$1:$F$1,0),0) -> Ft | J2: =VLOOKUP('Data 1'!$B2,'Data 2'!$A$1:$F$46,MATCH('Data 1'!J$1,'Data 2'!$A$1:$F$1,0),0) -> 144 | K2: =VLOOKUP('Data 1'!$B2,'Data 2'!$A$1:$F$46,MATCH('Data 1'!K$1,'Data 2'!$A$1:$F$1,0),0) -> 156.96 | L2: =SUM('Data 1'!$J2*'Data 1'!$C2) -> 1296 | M2: ='Data 1'!$C2*'Data 1'!$K2 -> 1412.64 | N2: ='Data 1'!$M2-'Data 1'!$L2 -> 116.64 | O2: =DAY('Data 1'!$A2) -> 1 | P2: =TEXT('Data 1'!$A2,"mmm") -> Jan | Q2: =YEAR('Data 1'!$A2) -> 2021
A3: 44198 | B3: P0038 | C3: 15 | D3: Online | E3: Cash | F3: 0 | G3: =VLOOKUP('Data 1'!$B3,'Data 2'!$A$1:$F$46,MATCH('Data 1'!G$1,'Data 2'!$A$1:$F$1,0),0) -> Product38 | H3: =VLOOKUP('Data 1'!$B3,'Data 2'!$A$1:$F$46,MATCH('Data 1'!H$1,'Data 2'!$A$1:$F$1,0),0) -> Category05 | I3: =VLOOKUP('Data 1'!$B3,'Data 2'!$A$1:$F$46,MATCH('Data 1'!I$1,'Data 2'!$A$1:$F$1,0),0) -> Kg | J3: =VLOOKUP('Data 1'!$B3,'Data 2'!$A$1:$F$46,MATCH('Data 1'!J$1,'Data 2'!$A$1:$F$1,0),0) -> 72 | K3: =VLOOKUP('Data 1'!$B3,'Data 2'!$A$1:$F$46,MATCH('Data 1'!K$1,'Data 2'!$A$1:$F$1,0),0) -> 79.92 | L3: =SUM('Data 1'!$J3*'Data 1'!$C3) -> 1080 | M3: ='Data 1'!$C3*'Data 1'!$K3 -> 1198.8 | N3: ='Data 1'!$M3-'Data 1'!$L3 -> 118.8 | O3: =DAY('Data 1'!$A3) -> 2 | P3: =TEXT('Data 1'!$A3,"mmm") -> Jan | Q3: =YEAR('Data 1'!$A3) -> 2021
A4: 44198 | B4: P0013 | C4: 6 | D4: Direct Sales | E4: Cash | F4: 0 | G4: =VLOOKUP('Data 1'!$B4,'Data 2'!$A$1:$F$46,MATCH('Data 1'!G$1,'Data 2'!$A$1:$F$1,0),0) -> Product13 | H4: =VLOOKUP('Data 1'!$B4,'Data 2'!$A$1:$F$46,MATCH('Data 1'!H$1,'Data 2'!$A$1:$F$1,0),0) -> Category02 | I4: =VLOOKUP('Data 1'!$B4,'Data 2'!$A$1:$F$46,MATCH('Data 1'!I$1,'Data 2'!$A$1:$F$1,0),0) -> Kg | J4: =VLOOKUP('Data 1'!$B4,'Data 2'!$A$1:$F$46,MATCH('Data 1'!J$1,'Data 2'!$A$1:$F$1,0),0) -> 112 | K4: =VLOOKUP('Data 1'!$B4,'Data 2'!$A$1:$F$46,MATCH('Data 1'!K$1,'Data 2'!$A$1:$F$1,0),0) -> 122.08 | L4: =SUM('Data 1'!$J4*'Data 1'!$C4) -> 672 | M4: ='Data 1'!$C4*'Data 1'!$K4 -> 732.48 | N4: ='Data 1'!$M4-'Data 1'!$L4 -> 60.48 | O4: =DAY('Data 1'!$A4) -> 2 | P4: =TEXT('Data 1'!$A4,"mmm") -> Jan | Q4: =YEAR('Data 1'!$A4) -> 2021
A5: 44199 | B5: P0004 | C5: 5 | D5: Direct Sales | E5: Online | F5: 0 | G5: =VLOOKUP('Data 1'!$B5,'Data 2'!$A$1:$F$46,MATCH('Data 1'!G$1,'Data 2'!$A$1:$F$1,0),0) -> Product04 | H5: =VLOOKUP('Data 1'!$B5,'Data 2'!$A$1:$F$46,MATCH('Data 1'!H$1,'Data 2'!$A$1:$F$1,0),0) -> Category01 | I5: =VLOOKUP('Data 1'!$B5,'Data 2'!$A$1:$F$46,MATCH('Data 1'!I$1,'Data 2'!$A$1:$F$1,0),0) -> Lt | J5: =VLOOKUP('Data 1'!$B5,'Data 2'!$A$1:$F$46,MATCH('Data 1'!J$1,'Data 2'!$A$1:$F$1,0),0) -> 44 | K5: =VLOOKUP('Data 1'!$B5,'Data 2'!$A$1:$F$46,MATCH('Data 1'!K$1,'Data 2'!$A$1:$F$1,0),0) -> 48.84 | L5: =SUM('Data 1'!$J5*'Data 1'!$C5) -> 220 | M5: ='Data 1'!$C5*'Data 1'!$K5 -> 244.2 | N5: ='Data 1'!$M5-'Data 1'!$L5 -> 24.2 | O5: =DAY('Data 1'!$A5) -> 3 | P5: =TEXT('Data 1'!$A5,"mmm") -> Jan | Q5: =YEAR('Data 1'!$A5) -> 2021
A6: 44200 | B6: P0035 | C6: 12 | D6: Online | E6: Online | F6: 0 | G6: =VLOOKUP('Data 1'!$B6,'Data 2'!$A$1:$F$46,MATCH('Data 1'!G$1,'Data 2'!$A$1:$F$1,0),0) -> Product35 | H6: =VLOOKUP('Data 1'!$B6,'Data 2'!$A$1:$F$46,MATCH('Data 1'!H$1,'Data 2'!$A$1:$F$1,0),0) -> Category04 | I6: =VLOOKUP('Data 1'!$B6,'Data 2'!$A$1:$F$46,MATCH('Data 1'!I$1,'Data 2'!$A$1:$F$1,0),0) -> No. | J6: =VLOOKUP('Data 1'!$B6,'Data 2'!$A$1:$F$46,MATCH('Data 1'!J$1,'Data 2'!$A$1:$F$1,0),0) -> 5 | K6: =VLOOKUP('Data 1'!$B6,'Data 2'!$A$1:$F$46,MATCH('Data 1'!K$1,'Data 2'!$A$1:$F$1,0),0) -> 6.7 | L6: =SUM('Data 1'!$J6*'Data 1'!$C6) -> 60 | M6: ='Data 1'!$C6*'Data 1'!$K6 -> 80.4 | N6: ='Data 1'!$M6-'Data 1'!$L6 -> 20.4 | O6: =DAY('Data 1'!$A6) -> 4 | P6: =TEXT('Data 1'!$A6,"mmm") -> Jan | Q6: =YEAR('Data 1'!$A6) -> 2021
A7: 44205 | B7: P0031 | C7: 1 | D7: Direct Sales | E7: Cash | F7: 0 | G7: =VLOOKUP('Data 1'!$B7,'Data 2'!$A$1:$F$46,MATCH('Data 1'!G$1,'Data 2'!$A$1:$F$1,0),0) -> Product31 | H7: =VLOOKUP('Data 1'!$B7,'Data 2'!$A$1:$F$46,MATCH('Data 1'!H$1,'Data 2'!$A$1:$F$1,0),0) -> Category04 | I7: =VLOOKUP('Data 1'!$B7,'Data 2'!$A$1:$F$46,MATCH('Data 1'!I$1,'Data 2'!$A$1:$F$1,0),0) -> Kg | J7: =VLOOKUP('Data 1'!$B7,'Data 2'!$A$1:$F$46,MATCH('Data 1'!J$1,'Data 2'!$A$1:$F$1,0),0) -> 93 | K7: =VLOOKUP('Data 1'!$B7,'Data 2'!$A$1:$F$46,MATCH('Data 1'!K$1,'Data 2'!$A$1:$F$1,0),0) -> 104.16 | L7: =SUM('Data 1'!$J7*'Data 1'!$C7) -> 93 | M7: ='Data 1'!$C7*'Data 1'!$K7 -> 104.16 | N7: ='Data 1'!$M7-'Data 1'!$L7 -> 11.16 | O7: =DAY('Data 1'!$A7) -> 9 | P7: =TEXT('Data 1'!$A7,"mmm") -> Jan | Q7: =YEAR('Data 1'!$A7) -> 2021
A8: 44205 | B8: P0003 | C8: 8 | D8: Direct Sales | E8: Cash | F8: 0 | G8: =VLOOKUP('Data 1'!$B8,'Data 2'!$A$1:$F$46,MATCH('Data 1'!G$1,'Data 2'!$A$1:$F$1,0),0) -> Product03 | H8: =VLOOKUP('Data 1'!$B8,'Data 2'!$A$1:$F$46,MATCH('Data 1'!H$1,'Data 2'!$A$1:$F$1,0),0) -> Category01 | I8: =VLOOKUP('Data 1'!$B8,'Data 2'!$A$1:$F$46,MATCH('Data 1'!I$1,'Data 2'!$A$1:$F$1,0),0) -> Kg | J8: =VLOOKUP('Data 1'!$B8,'Data 2'!$A$1:$F$46,MATCH('Data 1'!J$1,'Data 2'!$A$1:$F$1,0),0) -> 71 | K8: =VLOOKUP('Data 1'!$B8,'Data 2'!$A$1:$F$46,MATCH('Data 1'!K$1,'Data 2'!$A$1:$F$1,0),0) -> 80.94 | L8: =SUM('Data 1'!$J8*'Data 1'!$C8) -> 568 | M8: ='Data 1'!$C8*'Data 1'!$K8 -> 647.52 | N8: ='Data 1'!$M8-'Data 1'!$L8 -> 79.52 | O8: =DAY('Data 1'!$A8) -> 9 | P8: =TEXT('Data 1'!$A8,"mmm") -> Jan | Q8: =YEAR('Data 1'!$A8) -> 2021
A9: 44205 | B9: P0025 | C9: 4 | D9: Direct Sales | E9: Online | F9: 0 | G9: =VLOOKUP('Data 1'!$B9,'Data 2'!$A$1:$F$46,MATCH('Data 1'!G$1,'Data 2'!$A$1:$F$1,0),0) -> Product25 | H9: =VLOOKUP('Data 1'!$B9,'Data 2'!$A$1:$F$46,MATCH('Data 1'!H$1,'Data 2'!$A$1:$F$1,0),0) -> Category03 | I9: =VLOOKUP('Data 1'!$B9,'Data 2'!$A$1:$F$46,MATCH('Data 1'!I$1,'Data 2'!$A$1:$F$1,0),0) -> No. | J9: =VLOOKUP('Data 1'!$B9,'Data 2'!$A$1:$F$46,MATCH('Data 1'!J$1,'Data 2'!$A$1:$F$1,0),0) -> 7 | K9: =VLOOKUP('Data 1'!$B9,'Data 2'!$A$1:$F$46,MATCH('Data 1'!K$1,'Data 2'!$A$1:$F$1,0),0) -> 8.33 | L9: =SUM('Data 1'!$J9*'Data 1'!$C9) -> 28 | M9: ='Data 1'!$C9*'Data 1'!$K9 -> 33.32 | N9: ='Data 1'!$M9-'Data 1'!$L9 -> 5.32 | O9: =DAY('Data 1'!$A9) -> 9 | P9: =TEXT('Data 1'!$A9,"mmm") -> Jan | Q9: =YEAR('Data 1'!$A9) -> 2021
A10: 44207 | B10: P0037 | C10: 3 | D10: Direct Sales | E10: Cash | F10: 0 | G10: =VLOOKUP('Data 1'!$B10,'Data 2'!$A$1:$F$46,MATCH('Data 1'!G$1,'Data 2'!$A$1:$F$1,0),0) -> Product37 | H10: =VLOOKUP('Data 1'!$B10,'Data 2'!$A$1:$F$46,MATCH('Data 1'!H$1,'Data 2'!$A$1:$F$1,0),0) -> Category05 | I10: =VLOOKUP('Data 1'!$B10,'Data 2'!$A$1:$F$46,MATCH('Data 1'!I$1,'Data 2'!$A$1:$F$1,0),0) -> Kg | J10: =VLOOKUP('Data 1'!$B10,'Data 2'!$A$1:$F$46,MATCH('Data 1'!J$1,'Data 2'!$A$1:$F$1,0),0) -> 67 | K10: =VLOOKUP('Data 1'!$B10,'Data 2'!$A$1:$F$46,MATCH('Data 1'!K$1,'Data 2'!$A$1:$F$1,0),0) -> 85.76 | L10: =SUM('Data 1'!$J10*'Data 1'!$C10) -> 201 | M10: ='Data 1'!$C10*'Data 1'!$K10 -> 257.28 | N10: ='Data 1'!$M10-'Data 1'!$L10 -> 56.28 | O10: =DAY('Data 1'!$A10) -> 11 | P10: =TEXT('Data 1'!$A10,"mmm") -> Jan | Q10: =YEAR('Data 1'!$A10) -> 2021
A11: 44207 | B11: P0014 | C11: 4 | D11: Wholesaler | E11: Online | F11: 0 | G11: =VLOOKUP('Data 1'!$B11,'Data 2'!$A$1:$F$46,MATCH('Data 1'!G$1,'Data 2'!$A$1:$F$1,0),0) -> Product14 | H11: =VLOOKUP('Data 1'!$B11,'Data 2'!$A$1:$F$46,MATCH('Data 1'!H$1,'Data 2'!$A$1:$F$1,0),0) -> Category02 | I11: =VLOOKUP('Data 1'!$B11,'Data 2'!$A$1:$F$46,MATCH('Data 1'!I$1,'Data 2'!$A$1:$F$1,0),0) -> Kg | J11: =VLOOKUP('Data 1'!$B11,'Data 2'!$A$1:$F$46,MATCH('Data 1'!J$1,'Data 2'!$A$1:$F$1,0),0) -> 112 | K11: =VLOOKUP('Data 1'!$B11,'Data 2'!$A$1:$F$46,MATCH('Data 1'!K$1,'Data 2'!$A$1:$F$1,0),0) -> 146.72 | L11: =SUM('Data 1'!$J11*'Data 1'!$C11) -> 448 | M11: ='Data 1'!$C11*'Data 1'!$K11 -> 586.88 | N11: ='Data 1'!$M11-'Data 1'!$L11 -> 138.88 | O11: =DAY('Data 1'!$A11) -> 11 | P11: =TEXT('Data 1'!$A11,"mmm") -> Jan | Q11: =YEAR('Data 1'!$A11) -> 2021
A12: 44207 | B12: P0042 | C12: 4 | D12: Direct Sales | E12: Online | F12: 0 | G12: =VLOOKUP('Data 1'!$B12,'Data 2'!$A$1:$F$46,MATCH('Data 1'!G$1,'Data 2'!$A$1:$F$1,0),0) -> Product42 | H12: =VLOOKUP('Data 1'!$B12,'Data 2'!$A$1:$F$46,MATCH('Data 1'!H$1,'Data 2'!$A$1:$F$1,0),0) -> Category05 | I12: =VLOOKUP('Data 1'!$B12,'Data 2'!$A$1:$F$46,MATCH('Data 1'!I$1,'Data 2'!$A$1:$F$1,0),0) -> Ft | J12: =VLOOKUP('Data 1'!$B12,'Data 2'!$A$1:$F$46,MATCH('Data 1'!J$1,'Data 2'!$A$1:$F$1,0),0) -> 120 | K12: =VLOOKUP('Data 1'!$B12,'Data 2'!$A$1:$F$46,MATCH('Data 1'!K$1,'Data 2'!$A$1:$F$1,0),0) -> 162 | L12: =SUM('Data 1'!$J12*'Data 1'!$C12) -> 480 | M12: ='Data 1'!$C12*'Data 1'!$K12 -> 648 | N12: ='Data 1'!$M12-'Data 1'!$L12 -> 168 | O12: =DAY('Data 1'!$A12) -> 11 | P12: =TEXT('Data 1'!$A12,"mmm") -> Jan | Q12: =YEAR('Data 1'!$A12) -> 2021
A13: 44208 | B13: P0042 | C13: 10 | D13: Online | E13: Cash | F13: 0 | G13: =VLOOKUP('Data 1'!$B13,'Data 2'!$A$1:$F$46,MATCH('Data 1'!G$1,'Data 2'!$A$1:$F$1,0),0) -> Product42 | H13: =VLOOKUP('Data 1'!$B13,'Data 2'!$A$1:$F$46,MATCH('Data 1'!H$1,'Data 2'!$A$1:$F$1,0),0) -> Category05 | I13: =VLOOKUP('Data 1'!$B13,'Data 2'!$A$1:$F$46,MATCH('Data 1'!I$1,'Data 2'!$A$1:$F$1,0),0) -> Ft | J13: =VLOOKUP('Data 1'!$B13,'Data 2'!$A$1:$F$46,MATCH('Data 1'!J$1,'Data 2'!$A$1:$F$1,0),0) -> 120 | K13: =VLOOKUP('Data 1'!$B13,'Data 2'!$A$1:$F$46,MATCH('Data 1'!K$1,'Data 2'!$A$1:$F$1,0),0) -> 162 | L13: =SUM('Data 1'!$J13*'Data 1'!$C13) -> 1200 | M13: ='Data 1'!$C13*'Data 1'!$K13 -> 1620 | N13: ='Data 1'!$M13-'Data 1'!$L13 -> 420 | O13: =DAY('Data 1'!$A13) -> 12 | P13: =TEXT('Data 1'!$A13,"mmm") -> Jan | Q13: =YEAR('Data 1'!$A13) -> 2021
... A528: 44926 | B528: P0011 | C528: 3 | D528: Wholesaler | E528: Cash | F528: 0 | G528: =VLOOKUP('Data 1'!$B528,'Data 2'!$A$1:$F$46,MATCH('Data 1'!G$1,'Data 2'!$A$1:$F$1,0),0) -> Product11 | H528: =VLOOKUP('Data 1'!$B528,'Data 2'!$A$1:$F$46,MATCH('Data 1'!H$1,'Data 2'!$A$1:$F$1,0),0) -> Category02 | I528: =VLOOKUP('Data 1'!$B528,'Data 2'!$A$1:$F$46,MATCH('Data 1'!I$1,'Data 2'!$A$1:$F$1,0),0) -> Lt | J528: =VLOOKUP('Data 1'!$B528,'Data 2'!$A$1:$F$46,MATCH('Data 1'!J$1,'Data 2'!$A$1:$F$1,0),0) -> 44 | K528: =VLOOKUP('Data 1'!$B528,'Data 2'!$A$1:$F$46,MATCH('Data 1'!K$1,'Data 2'!$A$1:$F$1,0),0) -> 48.4 | L528: =SUM('Data 1'!$J528*'Data 1'!$C528) -> 132 | M528: ='Data 1'!$C528*'Data 1'!$K528 -> 145.2 | N528: ='Data 1'!$M528-'Data 1'!$L528 -> 13.2 | O528: =DAY('Data 1'!$A528) -> 31 | P528: =TEXT('Data 1'!$A528,"mmm") -> Dec | Q528: =YEAR('Data 1'!$A528) -> 2022

Sheet Data 2
A1: PRODUCT ID | B1: PRODUCT | C1: CATEGORY | D1: UOM | E1: BUYING PRIZE | F1: SELLING PRICE
A2: P0001 | B2: Product01 | C2: Category01 | D2: Kg | E2: 98 | F2: 103.88
A3: P0002 | B3: Product02 | C3: Category01 | D3: Kg | E3: 105 | F3: 142.8
A4: P0003 | B4: Product03 | C4: Category01 | D4: Kg | E4: 71 | F4: 80.94
A5: P0004 | B5: Product04 | C5: Category01 | D5: Lt | E5: 44 | F5: 48.84
A6: P0005 | B6: Product05 | C6: Category01 | D6: Ft | E6: 133 | F6: 155.61
A7: P0006 | B7: Product06 | C7: Category01 | D7: Kg | E7: 75 | F7: 85.5
A8: P0007 | B8: Product07 | C8: Category01 | D8: Lt | E8: 43 | F8: 47.73
A9: P0008 | B9: Product08 | C9: Category01 | D9: Kg | E9: 83 | F9: 94.62
A10: P0009 | B10: Product09 | C10: Category03 | D10: No. | E10: 6 | F10: 7.86
A11: P0010 | B11: Product10 | C11: Category02 | D11: Ft | E11: 148 | F11: 164.28
A12: P0011 | B12: Product11 | C12: Category02 | D12: Lt | E12: 44 | F12: 48.4
A13: P0012 | B13: Product12 | C13: Category02 | D13: Kg | E13: 73 | F13: 94.17
... A46: P0045 | B46: Product45 | C46: Category05 | D46: Kg | E46: 50 | F46: 62

Sheet Requirements
A1: Total Buying
A2: Total Sales
A3: Total Profit
A4: Profit%
A6: Year Wise sales,profit,Buying prize
A7: Day wise Sales
A8: Category wise sales
A9: Sale type wise sales
A10: Payment mode wise sales
A12: Top Product name and sales
A13: Top category name and sales
A14: Month wise Profit % and sales in combo chart

Sheet Dashboard

Sheet Sheet2
